Workbook

Sheet Ventas
A1: FECHA_CARGA | B1: N° REMITO | C1: VENDEDOR | D1: FECHA | E1: LÍNEA | F1: COD | G1: CANTIDAD | H1: CLIENTE | I1: COMIS% | J1: PRECIO UNIT | K1: SUBTOTAL | L1: AÑO-MES | M1: COMENTARIOS | N1: CMV | O1: MARGEN | P1: MARCA | Q1: TIPO CLIENTE | R1: ZONA | S1: LOCALIDAD | T1: PROVINCIA | U1: DESCRIPCION
B2: 1144 | C2: Maxi | D2: 45965 | E2: MONCAR | F2: CF 671 | G2: 5 | H2: IONLUX | J2: =IF(TRIM(F2)="","",IF(LEFT(TRIM(F2),2)="RM",IFERROR(IF(D2>=DATE(2026,4,1),INDEX('LP RMH'!$F:$F,MATCH(TRIM(F2),'LP RMH'!$A:$A,0)),INDEX('LP RMH'!$E:$E,MATCH(TRIM(F2),'LP RMH'!$A:$A,0))),0),IFERROR(INDEX('LP MONCAR'!$E:$E,MATCH(TRIM(F2),'LP MONCAR'!$A:$A,0)),0))) | K2: 16550 | L2: 2025-11 | P2: BLACK Y DECKER | Q2: FERRETERIA | U2: DESCRIPCION (auto)
B3: 1144 | C3: Maxi | D3: 45965 | E3: MONCAR | F3: CF 020 | G3: 15 | H3: IONLUX | J3: =IF(TRIM(F3)="","",IF(LEFT(TRIM(F3),2)="RM",IFERROR(IF(D3>=DATE(2026,4,1),INDEX('LP RMH'!$F:$F,MATCH(TRIM(F3),'LP RMH'!$A:$A,0)),INDEX('LP RMH'!$E:$E,MATCH(TRIM(F3),'LP RMH'!$A:$A,0))),0),IFERROR(INDEX('LP MONCAR'!$E:$E,MATCH(TRIM(F3),'LP MONCAR'!$A:$A,0)),0))) | K3: 76950 | L3: 2025-11 | N3: 10298.147 | O3: 66651.853 | P3: BOSCH | Q3: FERRETERIA
B4: 1144 | C4: Maxi | D4: 45965 | E4: MONCAR | F4: CF 711 | G4: 5 | H4: IONLUX | J4: =IF(TRIM(F4)="","",IF(LEFT(TRIM(F4),2)="RM",IFERROR(IF(D4>=DATE(2026,4,1),INDEX('LP RMH'!$F:$F,MATCH(TRIM(F4),'LP RMH'!$A:$A,0)),INDEX('LP RMH'!$E:$E,MATCH(TRIM(F4),'LP RMH'!$A:$A,0))),0),IFERROR(INDEX('LP MONCAR'!$E:$E,MATCH(TRIM(F4),'LP MONCAR'!$A:$A,0)),0))) | K4: 15300 | L4: 2025-11 | N4: 2537.2245 | O4: 12762.775 | P4: GAMMA | Q4: FERRETERIA
B5: 1144 | C5: Maxi | D5: 45965 | E5: MONCAR | F5: CF 040 | G5: 10 | H5: IONLUX | J5: =IF(TRIM(F5)="","",IF(LEFT(TRIM(F5),2)="RM",IFERROR(IF(D5>=DATE(2026,4,1),INDEX('LP RMH'!$F:$F,MATCH(TRIM(F5),'LP RMH'!$A:$A,0)),INDEX('LP RMH'!$E:$E,MATCH(TRIM(F5),'LP RMH'!$A:$A,0))),0),IFERROR(INDEX('LP MONCAR'!$E:$E,MATCH(TRIM(F5),'LP MONCAR'!$A:$A,0)),0))) | K5: 49300 | L5: 2025-11 | N5: 6566.934 | O5: 42733.066 | P5: HITACHI | Q5: FERRETERIA
B6: 1144 | C6: Maxi | D6: 45965 | E6: MONCAR | F6: CF 042 | G6: 5 | H6: IONLUX | J6: =IF(TRIM(F6)="","",IF(LEFT(TRIM(F6),2)="RM",IFERROR(IF(D6>=DATE(2026,4,1),INDEX('LP RMH'!$F:$F,MATCH(TRIM(F6),'LP RMH'!$A:$A,0)),INDEX('LP RMH'!$E:$E,MATCH(TRIM(F6),'LP RMH'!$A:$A,0))),0),IFERROR(INDEX('LP MONCAR'!$E:$E,MATCH(TRIM(F6),'LP MONCAR'!$A:$A,0)),0))) | K6: 25150 | L6: 2025-11 | N6: 3283.467 | O6: 21866.533 | P6: HITACHI | Q6: FERRETERIA
B7: 1144 | C7: Maxi | D7: 45965 | E7: MONCAR | F7: CF 658 | G7: 5 | H7: IONLUX | J7: =IF(TRIM(F7)="","",IF(LEFT(TRIM(F7),2)="RM",IFERROR(IF(D7>=DATE(2026,4,1),INDEX('LP RMH'!$F:$F,MATCH(TRIM(F7),'LP RMH'!$A:$A,0)),INDEX('LP RMH'!$E:$E,MATCH(TRIM(F7),'LP RMH'!$A:$A,0))),0),IFERROR(INDEX('LP MONCAR'!$E:$E,MATCH(TRIM(F7),'LP MONCAR'!$A:$A,0)),0))) | K7: 12650 | L7: 2025-11 | N7: 1641.7335 | O7: 11008.266 | P7: SKIL | Q7: FERRETERIA
B8: 1145 | C8: Maxi | D8: 45965 | E8: MONCAR | F8: CF 665 | G8: 4 | H8: FERRETERIA MAX | J8: =IF(TRIM(F8)="","",IF(LEFT(TRIM(F8),2)="RM",IFERROR(IF(D8>=DATE(2026,4,1),INDEX('LP RMH'!$F:$F,MATCH(TRIM(F8),'LP RMH'!$A:$A,0)),INDEX('LP RMH'!$E:$E,MATCH(TRIM(F8),'LP RMH'!$A:$A,0))),0),IFERROR(INDEX('LP MONCAR'!$E:$E,MATCH(TRIM(F8),'LP MONCAR'!$A:$A,0)),0))) | K8: 9200 | L8: 2025-11 | N8: 1193.988 | O8: 8006.012 | P8: BLACK Y DECKER | Q8: FERRETERIA | R8: CABA
B9: 1145 | C9: Maxi | D9: 45965 | E9: MONCAR | F9: CF 190 | G9: 2 | H9: FERRETERIA MAX | J9: =IF(TRIM(F9)="","",IF(LEFT(TRIM(F9),2)="RM",IFERROR(IF(D9>=DATE(2026,4,1),INDEX('LP RMH'!$F:$F,MATCH(TRIM(F9),'LP RMH'!$A:$A,0)),INDEX('LP RMH'!$E:$E,MATCH(TRIM(F9),'LP RMH'!$A:$A,0))),0),IFERROR(INDEX('LP MONCAR'!$E:$E,MATCH(TRIM(F9),'LP MONCAR'!$A:$A,0)),0))) | K9: 6840 | L9: 2025-11 | N9: 895.491 | O9: 5944.509 | P9: DE WALT | Q9: FERRETERIA | R9: CABA
B10: 1145 | C10: Maxi | D10: 45965 | E10: MONCAR | F10: CF 711 | G10: 2 | H10: FERRETERIA MAX | J10: =IF(TRIM(F10)="","",IF(LEFT(TRIM(F10),2)="RM",IFERROR(IF(D10>=DATE(2026,4,1),INDEX('LP RMH'!$F:$F,MATCH(TRIM(F10),'LP RMH'!$A:$A,0)),INDEX('LP RMH'!$E:$E,MATCH(TRIM(F10),'LP RMH'!$A:$A,0))),0),IFERROR(INDEX('LP MONCAR'!$E:$E,MATCH(TRIM(F10),'LP MONCAR'!$A:$A,0)),0))) | K10: 6120 | L10: 2025-11 | N10: 1014.8898 | O10: 5105.1102 | P10: GAMMA | Q10: FERRETERIA | R10: CABA
B11: 1145 | C11: Maxi | D11: 45965 | E11: MONCAR | F11: CF 661 | G11: 2 | H11: FERRETERIA MAX | J11: =IF(TRIM(F11)="","",IF(LEFT(TRIM(F11),2)="RM",IFERROR(IF(D11>=DATE(2026,4,1),INDEX('LP RMH'!$F:$F,MATCH(TRIM(F11),'LP RMH'!$A:$A,0)),INDEX('LP RMH'!$E:$E,MATCH(TRIM(F11),'LP RMH'!$A:$A,0))),0),IFERROR(INDEX('LP MONCAR'!$E:$E,MATCH(TRIM(F11),'LP MONCAR'!$A:$A,0)),0))) | K11: 6840 | L11: 2025-11 | N11: 895.491 | O11: 5944.509 | P11: SKIL | Q11: FERRETERIA | R11: CABA
B12: 1146 | C12: Maxi | D12: 45967 | E12: MONCAR | F12: CF 665 | G12: 6 | H12: MAQTOOLS | J12: =IF(TRIM(F12)="","",IF(LEFT(TRIM(F12),2)="RM",IFERROR(IF(D12>=DATE(2026,4,1),INDEX('LP RMH'!$F:$F,MATCH(TRIM(F12),'LP RMH'!$A:$A,0)),INDEX('LP RMH'!$E:$E,MATCH(TRIM(F12),'LP RMH'!$A:$A,0))),0),IFERROR(INDEX('LP MONCAR'!$E:$E,MATCH(TRIM(F12),'LP MONCAR'!$A:$A,0)),0))) | K12: 13800 | L12: 2025-11 | N12: 1790.982 | O12: 12009.018 | P12: BLACK Y DECKER | Q12: FERRETERIA | R12: CABA
B13: 1146 | C13: Maxi | D13: 45967 | E13: MONCAR | F13: CF 180 | G13: 2 | H13: MAQTOOLS | J13: =IF(TRIM(F13)="","",IF(LEFT(TRIM(F13),2)="RM",IFERROR(IF(D13>=DATE(2026,4,1),INDEX('LP RMH'!$F:$F,MATCH(TRIM(F13),'LP RMH'!$A:$A,0)),INDEX('LP RMH'!$E:$E,MATCH(TRIM(F13),'LP RMH'!$A:$A,0))),0),IFERROR(INDEX('LP MONCAR'!$E:$E,MATCH(TRIM(F13),'LP MONCAR'!$A:$A,0)),0))) | K13: 8280 | L13: 2025-11 | N13: 1074.5892 | O13: 7205.4108 | P13: DE WALT | Q13: FERRETERIA | R13: CABA
B14: 1146 | C14: Maxi | D14: 45967 | E14: MONCAR | F14: CF 183 | G14: 2 | H14: MAQTOOLS | J14: =IF(TRIM(F14)="","",IF(LEFT(TRIM(F14),2)="RM",IFERROR(IF(D14>=DATE(2026,4,1),INDEX('LP RMH'!$F:$F,MATCH(TRIM(F14),'LP RMH'!$A:$A,0)),INDEX('LP RMH'!$E:$E,MATCH(TRIM(F14),'LP RMH'!$A:$A,0))),0),IFERROR(INDEX('LP MONCAR'!$E:$E,MATCH(TRIM(F14),'LP MONCAR'!$A:$A,0)),0))) | K14: 10600 | L14: 2025-11 | N14: 1373.0862 | O14: 9226.9138 | P14: DE WALT | Q14: FERRETERIA | R14: CABA
B15: 1146 | C15: Maxi | D15: 45967 | E15: MONCAR | F15: CF 192 | G15: 2 | H15: MAQTOOLS | J15: =IF(TRIM(F15)="","",IF(LEFT(TRIM(F15),2)="RM",IFERROR(IF(D15>=DATE(2026,4,1),INDEX('LP RMH'!$F:$F,MATCH(TRIM(F15),'LP RMH'!$A:$A,0)),INDEX('LP RMH'!$E:$E,MATCH(TRIM(F15),'LP RMH'!$A:$A,0))),0),IFERROR(INDEX('LP MONCAR'!$E:$E,MATCH(TRIM(F15),'LP MONCAR'!$A:$A,0)),0))) | K15: 6440 | L15: 2025-11 | N15: 835.7916 | O15: 5604.2084 | P15: DE WALT | Q15: FERRETERIA | R15: CABA
B16: 1146 | C16: Maxi | D16: 45967 | E16: MONCAR | F16: CF 002 | G16: 4 | H16: MAQTOOLS | J16: =IF(TRIM(F16)="","",IF(LEFT(TRIM(F16),2)="RM",IFERROR(IF(D16>=DATE(2026,4,1),INDEX('LP RMH'!$F:$F,MATCH(TRIM(F16),'LP RMH'!$A:$A,0)),INDEX('LP RMH'!$E:$E,MATCH(TRIM(F16),'LP RMH'!$A:$A,0))),0),IFERROR(INDEX('LP MONCAR'!$E:$E,MATCH(TRIM(F16),'LP MONCAR'!$A:$A,0)),0))) | K16: 12880 | L16: 2025-11 | N16: 1671.5832 | O16: 11208.417 | P16: DOWEN PAGGIO | Q16: FERRETERIA | R16: CABA
B17: 1146 | C17: Maxi | D17: 45967 | E17: MONCAR | F17: CF 752 | G17: 1 | H17: MAQTOOLS | J17: =IF(TRIM(F17)="","",IF(LEFT(TRIM(F17),2)="RM",IFERROR(IF(D17>=DATE(2026,4,1),INDEX('LP RMH'!$F:$F,MATCH(TRIM(F17),'LP RMH'!$A:$A,0)),INDEX('LP RMH'!$E:$E,MATCH(TRIM(F17),'LP RMH'!$A:$A,0))),0),IFERROR(INDEX('LP MONCAR'!$E:$E,MATCH(TRIM(F17),'LP MONCAR'!$A:$A,0)),0))) | K17: 4380 | L17: 2025-11 | N17: 567.1443 | O17: 3812.8557 | P17: DOWEN PAGGIO | Q17: FERRETERIA | R17: CABA
B18: 1146 | C18: Maxi | D18: 45967 | E18: MONCAR | F18: CF 040 | G18: 2 | H18: MAQTOOLS | J18: =IF(TRIM(F18)="","",IF(LEFT(TRIM(F18),2)="RM",IFERROR(IF(D18>=DATE(2026,4,1),INDEX('LP RMH'!$F:$F,MATCH(TRIM(F18),'LP RMH'!$A:$A,0)),INDEX('LP RMH'!$E:$E,MATCH(TRIM(F18),'LP RMH'!$A:$A,0))),0),IFERROR(INDEX('LP MONCAR'!$E:$E,MATCH(TRIM(F18),'LP MONCAR'!$A:$A,0)),0))) | K18: 9860 | L18: 2025-11 | N18: 1313.3868 | O18: 8546.6132 | P18: HITACHI | Q18: FERRETERIA | R18: CABA
B19: 1146 | C19: Maxi | D19: 45967 | E19: MONCAR | F19: CF 056 | G19: 3 | H19: MAQTOOLS | J19: =IF(TRIM(F19)="","",IF(LEFT(TRIM(F19),2)="RM",IFERROR(IF(D19>=DATE(2026,4,1),INDEX('LP RMH'!$F:$F,MATCH(TRIM(F19),'LP RMH'!$A:$A,0)),INDEX('LP RMH'!$E:$E,MATCH(TRIM(F19),'LP RMH'!$A:$A,0))),0),IFERROR(INDEX('LP MONCAR'!$E:$E,MATCH(TRIM(F19),'LP MONCAR'!$A:$A,0)),0))) | K19: 15510 | L19: 2025-11 | N19: 2059.6293 | O19: 13450.371 | P19: MAKITA | Q19: FERRETERIA | R19: CABA
B20: 1121 | C20: Maxi | D20: 45958 | E20: MONCAR | F20: CF 665 | G20: 15 | H20: AYL MAQUINAS | J20: =IF(TRIM(F20)="","",IF(LEFT(TRIM(F20),2)="RM",IFERROR(IF(D20>=DATE(2026,4,1),INDEX('LP RMH'!$F:$F,MATCH(TRIM(F20),'LP RMH'!$A:$A,0)),INDEX('LP RMH'!$E:$E,MATCH(TRIM(F20),'LP RMH'!$A:$A,0))),0),IFERROR(INDEX('LP MONCAR'!$E:$E,MATCH(TRIM(F20),'LP MONCAR'!$A:$A,0)),0))) | K20: 34500 | L20: 2025-10 | N20: 4477.455 | O20: 30022.545 | P20: BLACK Y DECKER | Q20: FERRETERIA | R20: SANTIAGO DEL ESTERO | T20: Santiago Del Estero
B21: 1121 | C21: Maxi | D21: 45958 | E21: MONCAR | F21: CF 674 | G21: 20 | H21: AYL MAQUINAS | J21: =IF(TRIM(F21)="","",IF(LEFT(TRIM(F21),2)="RM",IFERROR(IF(D21>=DATE(2026,4,1),INDEX('LP RMH'!$F:$F,MATCH(TRIM(F21),'LP RMH'!$A:$A,0)),INDEX('LP RMH'!$E:$E,MATCH(TRIM(F21),'LP RMH'!$A:$A,0))),0),IFERROR(INDEX('LP MONCAR'!$E:$E,MATCH(TRIM(F21),'LP MONCAR'!$A:$A,0)),0))) | K21: 46000 | L21: 2025-10 | N21: 5969.94 | O21: 40030.06 | P21: BLACK Y DECKER | Q21: FERRETERIA | R21: SANTIAGO DEL ESTERO | T21: Santiago Del Estero
B22: 1121 | C22: Maxi | D22: 45958 | E22: MONCAR | F22: CF 017 | G22: 10 | H22: AYL MAQUINAS | J22: =IF(TRIM(F22)="","",IF(LEFT(TRIM(F22),2)="RM",IFERROR(IF(D22>=DATE(2026,4,1),INDEX('LP RMH'!$F:$F,MATCH(TRIM(F22),'LP RMH'!$A:$A,0)),INDEX('LP RMH'!$E:$E,MATCH(TRIM(F22),'LP RMH'!$A:$A,0))),0),IFERROR(INDEX('LP MONCAR'!$E:$E,MATCH(TRIM(F22),'LP MONCAR'!$A:$A,0)),0))) | K22: 34200 | L22: 2025-10 | N22: 4477.455 | O22: 29722.545 | P22: BOSCH | Q22: FERRETERIA | R22: SANTIAGO DEL ESTERO | T22: Santiago Del Estero
B23: 1121 | C23: Maxi | D23: 45958 | E23: MONCAR | F23: CF 614 | G23: 20 | H23: AYL MAQUINAS | J23: =IF(TRIM(F23)="","",IF(LEFT(TRIM(F23),2)="RM",IFERROR(IF(D23>=DATE(2026,4,1),INDEX('LP RMH'!$F:$F,MATCH(TRIM(F23),'LP RMH'!$A:$A,0)),INDEX('LP RMH'!$E:$E,MATCH(TRIM(F23),'LP RMH'!$A:$A,0))),0),IFERROR(INDEX('LP MONCAR'!$E:$E,MATCH(TRIM(F23),'LP MONCAR'!$A:$A,0)),0))) | K23: 74000 | L23: 2025-10 | N23: 9551.904 | O23: 64448.096 | P23: BOSCH | Q23: FERRETERIA | R23: SANTIAGO DEL ESTERO | T23: Santiago Del Estero
B24: 1121 | C24: Maxi | D24: 45958 | E24: MONCAR | F24: CF 002 | G24: 10 | H24: AYL MAQUINAS | J24: =IF(TRIM(F24)="","",IF(LEFT(TRIM(F24),2)="RM",IFERROR(IF(D24>=DATE(2026,4,1),INDEX('LP RMH'!$F:$F,MATCH(TRIM(F24),'LP RMH'!$A:$A,0)),INDEX('LP RMH'!$E:$E,MATCH(TRIM(F24),'LP RMH'!$A:$A,0))),0),IFERROR(INDEX('LP MONCAR'!$E:$E,MATCH(TRIM(F24),'LP MONCAR'!$A:$A,0)),0))) | K24: 32200 | L24: 2025-10 | N24: 4178.958 | O24: 28021.042 | P24: DOWEN PAGGIO | Q24: FERRETERIA | R24: SANTIAGO DEL ESTERO | T24: Santiago Del Estero
B25: 1121 | C25: Maxi | D25: 45958 | E25: MONCAR | F25: CF 003 | G25: 5 | H25: AYL MAQUINAS | J25: =IF(TRIM(F25)="","",IF(LEFT(TRIM(F25),2)="RM",IFERROR(IF(D25>=DATE(2026,4,1),INDEX('LP RMH'!$F:$F,MATCH(TRIM(F25),'LP RMH'!$A:$A,0)),INDEX('LP RMH'!$E:$E,MATCH(TRIM(F25),'LP RMH'!$A:$A,0))),0),IFERROR(INDEX('LP MONCAR'!$E:$E,MATCH(TRIM(F25),'LP MONCAR'!$A:$A,0)),0))) | K25: 12650 | L25: 2025-10 | N25: 1641.7335 | O25: 11008.266 | P25: DOWEN PAGGIO | Q25: FERRETERIA | R25: SANTIAGO DEL ESTERO | T25: Santiago Del Estero
B26: 1121 | C26: Maxi | D26: 45958 | E26: MONCAR | F26: CF 758 | G26: 15 | H26: AYL MAQUINAS | J26: =IF(TRIM(F26)="","",IF(LEFT(TRIM(F26),2)="RM",IFERROR(IF(D26>=DATE(2026,4,1),INDEX('LP RMH'!$F:$F,MATCH(TRIM(F26),'LP RMH'!$A:$A,0)),INDEX('LP RMH'!$E:$E,MATCH(TRIM(F26),'LP RMH'!$A:$A,0))),0),IFERROR(INDEX('LP MONCAR'!$E:$E,MATCH(TRIM(F26),'LP MONCAR'!$A:$A,0)),0))) | K26: 69000 | L26: 2025-10 | N26: 9402.6555 | O26: 59597.344 | P26: DOWEN PAGGIO | Q26: FERRETERIA | R26: SANTIAGO DEL ESTERO | T26: Santiago Del Estero
B27: 1121 | C27: Maxi | D27: 45958 | E27: MONCAR | F27: CF 040 | G27: 5 | H27: AYL MAQUINAS | J27: =IF(TRIM(F27)="","",IF(LEFT(TRIM(F27),2)="RM",IFERROR(IF(D27>=DATE(2026,4,1),INDEX('LP RMH'!$F:$F,MATCH(TRIM(F27),'LP RMH'!$A:$A,0)),INDEX('LP RMH'!$E:$E,MATCH(TRIM(F27),'LP RMH'!$A:$A,0))),0),IFERROR(INDEX('LP MONCAR'!$E:$E,MATCH(TRIM(F27),'LP MONCAR'!$A:$A,0)),0))) | K27: 24650 | L27: 2025-10 | N27: 3283.467 | O27: 21366.533 | P27: HITACHI | Q27: FERRETERIA | R27: SANTIAGO DEL ESTERO | T27: Santiago Del Estero
B28: 1121 | C28: Maxi | D28: 45958 | E28: MONCAR | F28: CF 041 | G28: 5 | H28: AYL MAQUINAS | J28: =IF(TRIM(F28)="","",IF(LEFT(TRIM(F28),2)="RM",IFERROR(IF(D28>=DATE(2026,4,1),INDEX('LP RMH'!$F:$F,MATCH(TRIM(F28),'LP RMH'!$A:$A,0)),INDEX('LP RMH'!$E:$E,MATCH(TRIM(F28),'LP RMH'!$A:$A,0))),0),IFERROR(INDEX('LP MONCAR'!$E:$E,MATCH(TRIM(F28),'LP MONCAR'!$A:$A,0)),0))) | K28: 12650 | L28: 2025-10 | N28: 1641.7335 | O28: 11008.266 | P28: HITACHI | Q28: FERRETERIA | R28: SANTIAGO DEL ESTERO | T28: Santiago Del Estero
B29: 1121 | C29: Maxi | D29: 45958 | E29: MONCAR | F29: CF 054 | G29: 10 | H29: AYL MAQUINAS | J29: =IF(TRIM(F29)="","",IF(LEFT(TRIM(F29),2)="RM",IFERROR(IF(D29>=DATE(2026,4,1),INDEX('LP RMH'!$F:$F,MATCH(TRIM(F29),'LP RMH'!$A:$A,0)),INDEX('LP RMH'!$E:$E,MATCH(TRIM(F29),'LP RMH'!$A:$A,0))),0),IFERROR(INDEX('LP MONCAR'!$E:$E,MATCH(TRIM(F29),'LP MONCAR'!$A:$A,0)),0))) | K29: 33800 | L29: 2025-10 | N29: 4477.455 | O29: 29322.545 | P29: MAKITA | Q29: FERRETERIA | R29: SANTIAGO DEL ESTERO | T29: Santiago Del Estero
B30: 1121 | C30: Maxi | D30: 45958 | E30: MONCAR | F30: CF 556 | G30: 5 | H30: AYL MAQUINAS | J30: =IF(TRIM(F30)="","",IF(LEFT(TRIM(F30),2)="RM",IFERROR(IF(D30>=DATE(2026,4,1),INDEX('LP RMH'!$F:$F,MATCH(TRIM(F30),'LP RMH'!$A:$A,0)),INDEX('LP RMH'!$E:$E,MATCH(TRIM(F30),'LP RMH'!$A:$A,0))),0),IFERROR(INDEX('LP MONCAR'!$E:$E,MATCH(TRIM(F30),'LP MONCAR'!$A:$A,0)),0))) | K30: 18500 | L30: 2025-10 | N30: 2387.976 | O30: 16112.024 | P30: MAKITA | Q30: FERRETERIA | R30: SANTIAGO DEL ESTERO | T30: Santiago Del Estero
B31: 1121 | C31: Maxi | D31: 45958 | E31: MONCAR | F31: CF 658 | G31: 5 | H31: AYL MAQUINAS | J31: =IF(TRIM(F31)="","",IF(LEFT(TRIM(F31),2)="RM",IFERROR(IF(D31>=DATE(2026,4,1),INDEX('LP RMH'!$F:$F,MATCH(TRIM(F31),'LP RMH'!$A:$A,0)),INDEX('LP RMH'!$E:$E,MATCH(TRIM(F31),'LP RMH'!$A:$A,0))),0),IFERROR(INDEX('LP MONCAR'!$E:$E,MATCH(TRIM(F31),'LP MONCAR'!$A:$A,0)),0))) | K31: 12650 | L31: 2025-10 | N31: 1641.7335 | O31: 11008.266 | P31: SKIL | Q31: FERRETERIA | R31: SANTIAGO DEL ESTERO | T31: Santiago Del Estero
B32: 1121 | C32: Maxi | D32: 45958 | E32: MONCAR | F32: CE 021 | G32: 5 | H32: AYL MAQUINAS | J32: =IF(TRIM(F32)="","",IF(LEFT(TRIM(F32),2)="RM",IFERROR(IF(D32>=DATE(2026,4,1),INDEX('LP RMH'!$F:$F,MATCH(TRIM(F32),'LP RMH'!$A:$A,0)),INDEX('LP RMH'!$E:$E,MATCH(TRIM(F32),'LP RMH'!$A:$A,0))),0),IFERROR(INDEX('LP MONCAR'!$E:$E,MATCH(TRIM(F32),'LP MONCAR'!$A:$A,0)),0))) | K32: 23950 | L32: 2025-10 | N32: 3432.7155 | O32: 20517.285 | P32: ENCERADORA | Q32: FERRETERIA | R32: SANTIAGO DEL ESTERO | T32: Santiago Del Estero
B33: 1097 | C33: Maxi | D33: 45944 | E33: MONCAR | F33: CF 675 | G33: 6 | H33: BURGOS | J33: =IF(TRIM(F33)="","",IF(LEFT(TRIM(F33),2)="RM",IFERROR(IF(D33>=DATE(2026,4,1),INDEX('LP RMH'!$F:$F,MATCH(TRIM(F33),'LP RMH'!$A:$A,0)),INDEX('LP RMH'!$E:$E,MATCH(TRIM(F33),'LP RMH'!$A:$A,0))),0),IFERROR(INDEX('LP MONCAR'!$E:$E,MATCH(TRIM(F33),'LP MONCAR'!$A:$A,0)),0))) | K33: 20520 | L33: 2025-10 | N33: 2686.473 | O33: 17833.527 | P33: BLACK Y DECKER | Q33: FERRETERIA
B34: 1097 | C34: Maxi | D34: 45944 | E34: MONCAR | F34: CF 180 | G34: 10 | H34: BURGOS | J34: =IF(TRIM(F34)="","",IF(LEFT(TRIM(F34),2)="RM",IFERROR(IF(D34>=DATE(2026,4,1),INDEX('LP RMH'!$F:$F,MATCH(TRIM(F34),'LP RMH'!$A:$A,0)),INDEX('LP RMH'!$E:$E,MATCH(TRIM(F34),'LP RMH'!$A:$A,0))),0),IFERROR(INDEX('LP MONCAR'!$E:$E,MATCH(TRIM(F34),'LP MONCAR'!$A:$A,0)),0))) | K34: 41400 | L34: 2025-10 | N34: 5372.946 | O34: 36027.054 | P34: DE WALT | Q34: FERRETERIA
B35: 1097 | C35: Maxi | D35: 45944 | E35: MONCAR | F35: CF 181 | G35: 5 | H35: BURGOS | J35: =IF(TRIM(F35)="","",IF(LEFT(TRIM(F35),2)="RM",IFERROR(IF(D35>=DATE(2026,4,1),INDEX('LP RMH'!$F:$F,MATCH(TRIM(F35),'LP RMH'!$A:$A,0)),INDEX('LP RMH'!$E:$E,MATCH(TRIM(F35),'LP RMH'!$A:$A,0))),0),IFERROR(INDEX('LP MONCAR'!$E:$E,MATCH(TRIM(F35),'LP MONCAR'!$A:$A,0)),0))) | K35: 17750 | L35: 2025-10 | N35: 2387.976 | O35: 15362.024 | P35: DE WALT | Q35: FERRETERIA
B36: 1097 | C36: Maxi | D36: 45944 | E36: MONCAR | F36: CF 711 | G36: 6 | H36: BURGOS | J36: =IF(TRIM(F36)="","",IF(LEFT(TRIM(F36),2)="RM",IFERROR(IF(D36>=DATE(2026,4,1),INDEX('LP RMH'!$F:$F,MATCH(TRIM(F36),'LP RMH'!$A:$A,0)),INDEX('LP RMH'!$E:$E,MATCH(TRIM(F36),'LP RMH'!$A:$A,0))),0),IFERROR(INDEX('LP MONCAR'!$E:$E,MATCH(TRIM(F36),'LP MONCAR'!$A:$A,0)),0))) | K36: 18360 | L36: 2025-10 | N36: 3044.6694 | O36: 15315.331 | P36: GAMMA | Q36: FERRETERIA
B37: 1097 | C37: Maxi | D37: 45944 | E37: MONCAR | F37: CF 648 | G37: 6 | H37: BURGOS | J37: =IF(TRIM(F37)="","",IF(LEFT(TRIM(F37),2)="RM",IFERROR(IF(D37>=DATE(2026,4,1),INDEX('LP RMH'!$F:$F,MATCH(TRIM(F37),'LP RMH'!$A:$A,0)),INDEX('LP RMH'!$E:$E,MATCH(TRIM(F37),'LP RMH'!$A:$A,0))),0),IFERROR(INDEX('LP MONCAR'!$E:$E,MATCH(TRIM(F37),'LP MONCAR'!$A:$A,0)),0))) | K37: 15180 | L37: 2025-10 | P37: SKIL | Q37: FERRETERIA
B38: 1097 | C38: Maxi | D38: 45944 | E38: MONCAR | F38: CF 658 | G38: 10 | H38: BURGOS | J38: =IF(TRIM(F38)="","",IF(LEFT(TRIM(F38),2)="RM",IFERROR(IF(D38>=DATE(2026,4,1),INDEX('LP RMH'!$F:$F,MATCH(TRIM(F38),'LP RMH'!$A:$A,0)),INDEX('LP RMH'!$E:$E,MATCH(TRIM(F38),'LP RMH'!$A:$A,0))),0),IFERROR(INDEX('LP MONCAR'!$E:$E,MATCH(TRIM(F38),'LP MONCAR'!$A:$A,0)),0))) | K38: 25300 | L38: 2025-10 | N38: 3283.467 | O38: 22016.533 | P38: SKIL | Q38: FERRETERIA
B39: 1097 | C39: Maxi | D39: 45944 | E39: MONCAR | F39: CE 307 | G39: 3 | H39: BURGOS | J39: =IF(TRIM(F39)="","",IF(LEFT(TRIM(F39),2)="RM",IFERROR(IF(D39>=DATE(2026,4,1),INDEX('LP RMH'!$F:$F,MATCH(TRIM(F39),'LP RMH'!$A:$A,0)),INDEX('LP RMH'!$E:$E,MATCH(TRIM(F39),'LP RMH'!$A:$A,0))),0),IFERROR(INDEX('LP MONCAR'!$E:$E,MATCH(TRIM(F39),'LP MONCAR'!$A:$A,0)),0))) | K39: 20130 | L39: 2025-10 | N39: 2686.473 | O39: 17443.527 | P39: HIDROLAVADORA | Q39: FERRETERIA
B40: 1097 | C40: Maxi | D40: 45944 | E40: MONCAR | F40: CE 308 | G40: 3 | H40: BURGOS | J40: =IF(TRIM(F40)="","",IF(LEFT(TRIM(F40),2)="RM",IFERROR(IF(D40>=DATE(2026,4,1),INDEX('LP RMH'!$F:$F,MATCH(TRIM(F40),'LP RMH'!$A:$A,0)),INDEX('LP RMH'!$E:$E,MATCH(TRIM(F40),'LP RMH'!$A:$A,0))),0),IFERROR(INDEX('LP MONCAR'!$E:$E,MATCH(TRIM(F40),'LP MONCAR'!$A:$A,0)),0))) | K40: 19800 | L40: 2025-10 | N40: 3044.6694 | O40: 16755.331 | P40: HIDROLAVADORA | Q40: FERRETERIA
...

Sheet LP MONCAR
A1: LISTA DE PRECIOS — Cambiá B2 para activar una nueva lista
A2: LP ACTIVA → | B2: LP 10 04.26 | C2: ← Cambiá este valor al nombre de la nueva LP cuando entre en vigencia
A3: COD | B3: EMPRESA | C3: MARCA | D3: DESCRIPCION | E3: LP 10 04.26
A4: CC 101 | B4: MONCAR | C4: COBREADOS | D4: ATORNILLADOR BOSCH GSR 180 | E4: 12190
A5: CC 102 | B5: MONCAR | C5: COBREADOS | D5: ATORNILLADOR MAKITA CB 440 | E5: 9600
A6: CE 001 | B6: MONCAR | D6: TURBION | E6: 6170
A7: CE 002 | B7: MONCAR | D7: INDUSTRIAL ULTRACOMB | E7: 4640
A8: CE 003 | B8: MONCAR | D8: INDUSTRIAL DISPROMAC - TURBION | E8: 5170
A9: CE 004 | B9: MONCAR | D9: INDUSTRIALES VARIAS | E9: 5460
A10: CE 005 | B10: MONCAR | D10: YELMO JET | E10: 5130
A11: CE 006 | B11: MONCAR | D11: INDUSTRIAL DIXTEL | E11: 5590
A12: CE 007 | B12: MONCAR | D12: INDUSTRIAL ALOÑA | E12: 5530
A13: CE 008 | B13: MONCAR | D13: MAQUINA PARA COSER BOLSAS DE COSECHADORA | E13: 3880
A14: CE 021 | B14: MONCAR | D14: YELMO-EXTRACHATAS-ULTRACOMB-VARIAS | E14: 5270
A15: CE 022 | B15: MONCAR | D15: YELMO-ULTRACOMB-ELECTROLUX | E15: 5270
A16: CE 023 | B16: MONCAR | D16: YELMO INTERNACIONAL | E16: 5270
A17: CE 024 | B17: MONCAR | D17: VARIAS | E17: 5270
... A61: CE 309 | B61: MONCAR | D61: HIDROLAVADORA | E61: 6120
A62: CF 001 | B62: MONCAR | C62: DOWEN PAGGIO | D62: LIJADORAS - PULIDORAS LIXA | E62: 3760
A63: CF 002 | B63: MONCAR | C63: DOWEN PAGGIO | D63: TALADROS MARK- NIG- NTX- LO- LV | E63: 3540
A64: CF 003 | B64: MONCAR | C64: DOWEN PAGGIO | D64: TALADROS MINI 8 Y 10- N 210/ 213/ 210 E/ 213 E/ 213 B | E64: 2780
A65: CF 004 | B65: MONCAR | C65: DOWEN PAGGIO | D65: RR | E65: 3760
A66: CF 005 | B66: MONCAR | C66: DOWEN PAGGIO | D66: AMOL. 7"- MOD. AL 180 | E66: 5590
A67: CF 009 | B67: MONCAR | C67: BLACK Y DECKER | D67: LINEA 700- TALADROS- CAL 2301/ 2303 LIJADORA/ TAL. VARIOS | E67: 2530
A68: CF 010 | B68: MONCAR | C68: BLACK Y DECKER | D68: TALADROS LINEA AR | E68: 3280
A69: CF 011 | B69: MONCAR | C69: BLACK Y DECKER | D69: AMOL. 4 1/2 "- SAG 500- CALADORA M 531 | E69: 3280
A70: CF 012 | B70: MONCAR | C70: BLACK Y DECKER | D70: KG 11/ KG75 (CON AVISO DE DESGASTE) | E70: 3380
A71: CF 013 | B71: MONCAR | C71: BLACK Y DECKER | D71: SIERRA CIRCULAR DE 7 1/4 " Y 9" | E71: 2200
A72: CF 014 | B72: MONCAR | C72: BLACK Y DECKER | D72: AMOLADORAS SMEA DE 7 " Y 9" | E72: 5500
A73: CF 015 | B73: MONCAR | C73: BLACK Y DECKER | D73: AMOLADORA AG/C- AMOL. 7" HD 2180- AMOL. 9" HD 2230 | E73: 5590
... A131: CF 183 | B131: MONCAR | C131: DE WALT | D131: D28490/D28491/D28496/D28474W/D28476W/D28494M/D28496M(CON AVISO DE DESGASTE) | E131: 5830
A132: CF 184 | B132: MONCAR | C132: DE WALT | E132: 3540
A133: CF 185 | B133: MONCAR | C133: DE WALT | D133: DW 861 CORTADORA DE HORMIGON CON AVISO DE DESGASTE | E133: 5310
A134: CF 186 | B134: MONCAR | C134: DE WALT | D134: CON AVISO DE DESGASTE | E134: 4070
A135: CF 187 | B135: MONCAR | C135: DE WALT | D135: D25103/D25013K/D25113//D25123K/D25303/D25124K/D25313K/D25114K(CON AVISO DESG.) | E135: 3540
A136: CF 188 | B136: MONCAR | C136: DE WALT | D136: CON AVISO DE DESGASTE DW621 FRESADORA | E136: 5300
A137: CF 189 | B137: MONCAR | C137: DE WALT | D137: D28111/D28112/D28136AR/D28143/D28136/D28114 (CON AVISO DE DESGASTE) | E137: 3760
A138: CF 190 | B138: MONCAR | C138: DE WALT | D138: DW402/DW411/DW412/DW421/LIJADORA D26441/D26451/CAL. DW313/318/317/331/433 | E138: 3760
A139: CF 191 | B139: MONCAR | C139: DE WALT | D139: DW476/DWDW848/DW852/DW498/DW849/DW478/DW492/DW852/DW892(CON AVISO DESG.) | E139: 5590
A140: CF 192 | B140: MONCAR | C140: DE WALT | D140: CON AVISO DESGASTE | E140: 3370
...

Sheet LP RMH
A1: LISTA DE PRECIOS RMH — Interruptores para maquinas electricas
A2: LP ACTIVA → | B2: Vigencia Abr-26 | C2: ← Cambia este valor cuando entre nueva vigencia
A3: COD | B3: EMPRESA | C3: MARCA | D3: DESCRIPCION | E3: Precio anterior | F3: Vigencia Abr-26
A4: RM 022 | B4: RMH | D4: Llave encendido hidrolavadora | E4: 4000 | F4: 4400
A5: RM 023 | B5: RMH | D5: Amoladora de banco | E5: 3650 | F5: 4015
A6: RM 026 | B6: RMH | D6: Lijadoras y cepillos | E6: 3650 | F6: 4015
A7: RM 029 | B7: RMH | D7: Amoladora angular 180mm | E7: 0 | F7: 9350
A8: RM 032 | B8: RMH | D8: Taladro 13mm | E8: 11000 | F8: 12100
A9: RM 033 | B9: RMH | D9: Taladro 13mm Stingray/Metabo | E9: 11600 | F9: 12760
A10: RM 034 | B10: RMH | D10: Amoladora 650W | E10: 6800 | F10: 7480
A11: RM 035 | B11: RMH | D11: Amoladora recta 4 1/2 | E11: 3850 | F11: 4235
A12: RM 036 | B12: RMH | D12: Amoladora con arranque progresivo | E12: 7400 | F12: 8140
A13: RM 040 | B13: RMH | D13: Amoladora Makita 9527/9524 | E13: 3650 | F13: 4015
A14: RM 041 | B14: RMH | D14: Palanca interruptor | E14: 3650 | F14: 4015
A15: RM 101 | B15: RMH | D15: Amoladora gatillo grande | E15: 19360 | F15: 19360
... A39: RM 718 | B39: RMH | D39: Sierra circular banco DWE7470 | E39: 38000 | F39: 41800

Sheet Costos
A1: COSTOS UNITARIOS — Actualizá TC en B2 (MONCAR) y E2 (RMH) para recalcular todo
A2: TC MONCAR: | B2: 1417.5 | D2: TC RMH: | E2: 1440 | G2: ← Editá estos valores para actualizar el CMV automáticamente
A4: COD | B4: LINEA | C4: MARCA | D4: COSTO USD | E4: COSTO PESOS | F4: PRECIO VENTA | G4: MARGEN BRUTO
A5: CE 001 | B5: MONCAR | C5: HOGAR | D5: 0.3 | E5: =D5*$B$2 | F5: 6170 | G5: =IFERROR(1-E5/F5,"")
A6: CE 006 | B6: MONCAR | C6: HOGAR | D6: 0.22 | E6: =D6*$B$2 | F6: 5590 | G6: =IFERROR(1-E6/F6,"")
A7: CE 021 | B7: MONCAR | C7: HOGAR | D7: 0.23 | E7: =D7*$B$2 | F7: 5270 | G7: =IFERROR(1-E7/F7,"")
A8: CE 022 | B8: MONCAR | C8: HOGAR | D8: 0.22 | E8: =D8*$B$2 | F8: 5270 | G8: =IFERROR(1-E8/F8,"")
A9: CE 023 | B9: MONCAR | C9: HOGAR | D9: 0.22 | E9: =D9*$B$2 | F9: 5270 | G9: =IFERROR(1-E9/F9,"")
A10: CE 044 | B10: MONCAR | C10: HOGAR | D10: 0.09 | E10: =D10*$B$2 | F10: 2530 | G10: =IFERROR(1-E10/F10,"")
A11: CE 045 | B11: MONCAR | C11: HOGAR | D11: 0.11 | E11: =D11*$B$2 | F11: 2780 | G11: =IFERROR(1-E11/F11,"")
A12: CE 302 | B12: MONCAR | C12: HOGAR | D12: 0.17 | E12: =D12*$B$2 | F12: 4280 | G12: =IFERROR(1-E12/F12,"")
A13: CE 303 | B13: MONCAR | C13: HOGAR | D13: 0.19 | E13: =D13*$B$2 | F13: 4800 | G13: =IFERROR(1-E13/F13,"")
A14: CE 304 | B14: MONCAR | C14: HOGAR | D14: 0.19 | E14: =D14*$B$2 | F14: 4800 | G14: =IFERROR(1-E14/F14,"")
A15: CE 307 | B15: MONCAR | C15: HOGAR | D15: 0.3 | E15: =D15*$B$2 | F15: 7380 | G15: =IFERROR(1-E15/F15,"")
A16: CE 308 | B16: MONCAR | C16: HOGAR | D16: 0.34 | E16: =D16*$B$2 | F16: 7260 | G16: =IFERROR(1-E16/F16,"")
... A180: CF 917 | B180: MONCAR | C180: BOSCH | D180: 0.16 | E180: =D180*$B$2 | F180: 4030 | G180: =IFERROR(1-E180/F180,"")
A181: RM 022 | B181: RMH | C181: RMH | D181: 1.892 | E181: =D181*$E$2 | F181: 4000 | G181: =IFERROR(1-E181/F181,"")
A182: RM 023 | B182: RMH | C182: RMH | D182: 1.842 | E182: =D182*$E$2 | F182: 3650 | G182: =IFERROR(1-E182/F182,"")
A183: RM 026 | B183: RMH | C183: RMH | D183: 1.842 | E183: =D183*$E$2 | F183: 3650 | G183: =IFERROR(1-E183/F183,"")
A184: RM 032 | B184: RMH | C184: RMH | D184: 2.742 | E184: =D184*$E$2 | F184: 11000 | G184: =IFERROR(1-E184/F184,"")
A185: RM 033 | B185: RMH | C185: RMH | D185: 2.742 | E185: =D185*$E$2 | F185: 11600 | G185: =IFERROR(1-E185/F185,"")
A186: RM 034 | B186: RMH | C186: RMH | D186: 2.192 | E186: =D186*$E$2 | F186: 6800 | G186: =IFERROR(1-E186/F186,"")
A187: RM 035 | B187: RMH | C187: RMH | D187: 1.872 | E187: =D187*$E$2 | F187: 3850 | G187: =IFERROR(1-E187/F187,"")
A188: RM 036 | B188: RMH | C188: RMH | D188: 2.132 | E188: =D188*$E$2 | F188: 7400 | G188: =IFERROR(1-E188/F188,"")
A189: RM 040 | B189: RMH | C189: RMH | D189: 1.762 | E189: =D189*$E$2 | F189: 3650 | G189: =IFERROR(1-E189/F189,"")
A190: RM 041 | B190: RMH | C190: RMH | D190: 1.802 | E190: =D190*$E$2 | F190: 3650 | G190: =IFERROR(1-E190/F190,"")
A191: RM 101 | B191: RMH | C191: RMH | D191: 2.692 | E191: =D191*$E$2 | F191: 17600 | G191: =IFERROR(1-E191/F191,"")
A192: RM 102 | B192: RMH | C192: RMH | D192: 2.722 | E192: =D192*$E$2 | F192: 17600 | G192: =IFERROR(1-E192/F192,"")
... A214: RM 718 | B214: RMH | C214: RMH | D214: 0 | E214: =D214*$E$2 | F214: 38000 | G214: =IFERROR(1-E214/F214,"")

Sheet Clientes
A1: CLIENTE | B1: CUIT | C1: TIPO CLIENTE | D1: ZONA | E1: LOCALIDAD | F1: PROVINCIA | G1: VENDEDOR | H1: % comisión venta
A2: AYL MAQUINAS | C2: FERRETERIA | D2: SANTIAGO DEL ESTERO | F2: Santiago Del Estero | G2: Maxi | H2: 0.3
A3: Adrian Basgall | C3: REPARADOR | E3: Jose C Paz | F3: Buenos Aires | G3: Franco | H3: 0.15
A4: BURGOS | C4: FERRETERIA | G4: Maxi | H4: 0.3
A5: Burgos German | C5: REPARADOR | G5: Maxi | H5: 0.3
A6: CASA FRANCHI | B6: 30710798881 | C6: FERRETERIA | G6: Maxi | H6: 0.3
A7: CASA SAENZ | B7: 30711229473 | C7: FERRETERIA | G7: Maxi | H7: 0.3
A8: CAMINO REAL | C8: FERRETERIA | G8: Maxi | H8: 0.3
A9: DEL VALLE | C9: FERRETERIA | G9: Maxi | H9: 0.3
A10: EL OBRADOR | C10: FERRETERIA | G10: Maxi | H10: 0.3
A11: ELECTROMECÁNICA GARDEÑES | C11: FERRETERIA | E11: Venado Tuerto | F11: Santa Fe | G11: Maxi | H11: 0.3
A12: EL REFUGIO | C12: FERRETERIA | G12: Maxi | H12: 0.3
A13: EL TIO | C13: FERRETERIA | G13: Maxi | H13: 0.3
A14: ELECTRO DIAMANTE | C14: FERRETERIA | D14: GBA-OESTE | G14: Maxi | H14: 0.3
A15: ELECTRO URIARTE | C15: FERRETERIA | E15: Banfield | G15: Maxi | H15: 0.3
A16: FERRETERIA CHARCAS | C16: FERRETERIA | G16: Maxi | H16: 0.3
A17: FERRETERIA DEVOTO | C17: FERRETERIA | D17: CABA | G17: Maxi | H17: 0.3
A18: FERRETERIA LISBOA | C18: FERRETERIA | E18: Lujan | F18: Buenos Aires | G18: Maxi | H18: 0.3
A19: FERRETERIA MAX | C19: FERRETERIA | D19: CABA | G19: Maxi | H19: 0.3
A20: FERRETERIA OLLEROS | C20: FERRETERIA | G20: Maxi | H20: 0.3
A21: FERRETERIA VESTO ROJAS | C21: FERRETERIA | G21: Maxi | H21: 0.3
A22: FERRETERIA GLACIAR | C22: FERRETERIA | G22: Maxi | H22: 0.3
A23: FERRETERIA ROSSI | C23: FERRETERIA | G23: Maxi | H23: 0.3
A24: GALLE | C24: FERRETERIA | D24: LA PLATA | E24: La Plata | F24: Buenos Aires | G24: Maxi | H24: 0.3
A25: IONLUX | B25: 20245150580 | C25: FERRETERIA | G25: Maxi | H25: 0.3
A26: LA GLORIA DE DIOS | C26: FERRETERIA | G26: Maxi | H26: 0.3
A27: LA ROTONDA | B27: 30716914530 | C27: FERRETERIA | G27: Maxi | H27: 0.3
A28: LOMDI | C28: FERRETERIA | G28: Maxi | H28: 0.3
A29: MAQTOOLS | C29: FERRETERIA | D29: CABA | E29: VILLA URQUIZA | G29: Maxi | H29: 0.3
A30: MECAN | B30: 30707431411 | C30: FERRETERIA | E30: Venado Tuerto | F30: Santa Fe | G30: Maxi | H30: 0.3
A31: MG | C31: FERRETERIA | G31: Maxi | H31: 0.3
A32: MONSALVO | C32: FERRETERIA | G32: Maxi | H32: 0.3
A33: PACIFICO 2 | B33: 30717230589 | C33: FERRETERIA | G33: Maxi | H33: 0.3
A34: PACIFICO | B34: 30711159653 | C34: FERRETERIA | G34: Maxi | H34: 0.3
A35: PACIFICO 3 | B35: 30711159653 | C35: FERRETERIA | G35: Maxi | H35: 0.3
A36: PACIFICO 4 | B36: 30718405579 | C36: FERRETERIA | G36: Maxi | H36: 0.3
A37: Poggi Daniel | C37: REPARADOR | G37: Maxi | H37: 0.3
A38: R.V | C38: FERRETERIA | D38: GBA-OESTE | E38: MORON | F38: Buenos Aires | G38: Maxi | H38: 0.3
A39: SERVISUR | C39: FERRETERIA | G39: Maxi | H39: 0.3
A40: ATLANTICO | B40: 33711159709 | C40: FERRETERIA | G40: Maxi | H40: 0.3
...
