Workbook

Sheet Buscador
A1: BUSCADOR DE EQUIVALENCIAS | MONCAR
A2: Escribe el codigo en la celda amarilla. Las equivalencias aparecen automaticamente.
A4: CODIGO A BUSCAR: | B4: CE 045 | C4: Ej: CF 001 | CF 055 | CF 751 | CE 044
A6: =IF($B$4="","Escribe un codigo en la celda amarilla.",IF(IFERROR(VLOOKUP($B$4,'Lista de Precios'!$A:$A,1,0),"")="","CODIGO NO ENCONTRADO en la lista de precios.",IF(IFERROR(VLOOKUP($B$4,'Tabla Equiv'!$A:$A,1,0),"")="","Este codigo NO tiene equivalencias.",""))) -> Este codigo NO tiene equivalencias.
A7: COD. EQUIVALENTE | B7: TERMINAL | C7: ESP | D7: ANCH | E7: LARG | F7: MARCA | G7: MODELOS Y APLICACIONES | H7: PRECIO UNIT
A8: =IFERROR(VLOOKUP($B$4,'Tabla Equiv'!$A:$I,2,0),"") | B8: =IF($A8="","",IFERROR(VLOOKUP($A8,'Lista de Precios'!$A:$H,2,0),"")) | C8: =IF($A8="","",IFERROR(VLOOKUP($A8,'Lista de Precios'!$A:$H,3,0),"")) | D8: =IF($A8="","",IFERROR(VLOOKUP($A8,'Lista de Precios'!$A:$H,4,0),"")) | E8: =IF($A8="","",IFERROR(VLOOKUP($A8,'Lista de Precios'!$A:$H,5,0),"")) | F8: =IF($A8="","",IFERROR(VLOOKUP($A8,'Lista de Precios'!$A:$H,6,0),"")) | G8: =IF($A8="","",IFERROR(VLOOKUP($A8,'Lista de Precios'!$A:$H,7,0),"")) | H8: =IF($A8="","",IFERROR(VLOOKUP($A8,'Lista de Precios'!$A:$H,8,0),""))
A9: =IFERROR(VLOOKUP($B$4,'Tabla Equiv'!$A:$I,3,0),"") | B9: =IF($A9="","",IFERROR(VLOOKUP($A9,'Lista de Precios'!$A:$H,2,0),"")) | C9: =IF($A9="","",IFERROR(VLOOKUP($A9,'Lista de Precios'!$A:$H,3,0),"")) | D9: =IF($A9="","",IFERROR(VLOOKUP($A9,'Lista de Precios'!$A:$H,4,0),"")) | E9: =IF($A9="","",IFERROR(VLOOKUP($A9,'Lista de Precios'!$A:$H,5,0),"")) | F9: =IF($A9="","",IFERROR(VLOOKUP($A9,'Lista de Precios'!$A:$H,6,0),"")) | G9: =IF($A9="","",IFERROR(VLOOKUP($A9,'Lista de Precios'!$A:$H,7,0),"")) | H9: =IF($A9="","",IFERROR(VLOOKUP($A9,'Lista de Precios'!$A:$H,8,0),""))
A10: =IFERROR(VLOOKUP($B$4,'Tabla Equiv'!$A:$I,4,0),"") | B10: =IF($A10="","",IFERROR(VLOOKUP($A10,'Lista de Precios'!$A:$H,2,0),"")) | C10: =IF($A10="","",IFERROR(VLOOKUP($A10,'Lista de Precios'!$A:$H,3,0),"")) | D10: =IF($A10="","",IFERROR(VLOOKUP($A10,'Lista de Precios'!$A:$H,4,0),"")) | E10: =IF($A10="","",IFERROR(VLOOKUP($A10,'Lista de Precios'!$A:$H,5,0),"")) | F10: =IF($A10="","",IFERROR(VLOOKUP($A10,'Lista de Precios'!$A:$H,6,0),"")) | G10: =IF($A10="","",IFERROR(VLOOKUP($A10,'Lista de Precios'!$A:$H,7,0),"")) | H10: =IF($A10="","",IFERROR(VLOOKUP($A10,'Lista de Precios'!$A:$H,8,0),""))
A11: =IFERROR(VLOOKUP($B$4,'Tabla Equiv'!$A:$I,5,0),"") | B11: =IF($A11="","",IFERROR(VLOOKUP($A11,'Lista de Precios'!$A:$H,2,0),"")) | C11: =IF($A11="","",IFERROR(VLOOKUP($A11,'Lista de Precios'!$A:$H,3,0),"")) | D11: =IF($A11="","",IFERROR(VLOOKUP($A11,'Lista de Precios'!$A:$H,4,0),"")) | E11: =IF($A11="","",IFERROR(VLOOKUP($A11,'Lista de Precios'!$A:$H,5,0),"")) | F11: =IF($A11="","",IFERROR(VLOOKUP($A11,'Lista de Precios'!$A:$H,6,0),"")) | G11: =IF($A11="","",IFERROR(VLOOKUP($A11,'Lista de Precios'!$A:$H,7,0),"")) | H11: =IF($A11="","",IFERROR(VLOOKUP($A11,'Lista de Precios'!$A:$H,8,0),""))
A12: =IFERROR(VLOOKUP($B$4,'Tabla Equiv'!$A:$I,6,0),"") | B12: =IF($A12="","",IFERROR(VLOOKUP($A12,'Lista de Precios'!$A:$H,2,0),"")) | C12: =IF($A12="","",IFERROR(VLOOKUP($A12,'Lista de Precios'!$A:$H,3,0),"")) | D12: =IF($A12="","",IFERROR(VLOOKUP($A12,'Lista de Precios'!$A:$H,4,0),"")) | E12: =IF($A12="","",IFERROR(VLOOKUP($A12,'Lista de Precios'!$A:$H,5,0),"")) | F12: =IF($A12="","",IFERROR(VLOOKUP($A12,'Lista de Precios'!$A:$H,6,0),"")) | G12: =IF($A12="","",IFERROR(VLOOKUP($A12,'Lista de Precios'!$A:$H,7,0),"")) | H12: =IF($A12="","",IFERROR(VLOOKUP($A12,'Lista de Precios'!$A:$H,8,0),""))
A13: =IFERROR(VLOOKUP($B$4,'Tabla Equiv'!$A:$I,7,0),"") | B13: =IF($A13="","",IFERROR(VLOOKUP($A13,'Lista de Precios'!$A:$H,2,0),"")) | C13: =IF($A13="","",IFERROR(VLOOKUP($A13,'Lista de Precios'!$A:$H,3,0),"")) | D13: =IF($A13="","",IFERROR(VLOOKUP($A13,'Lista de Precios'!$A:$H,4,0),"")) | E13: =IF($A13="","",IFERROR(VLOOKUP($A13,'Lista de Precios'!$A:$H,5,0),"")) | F13: =IF($A13="","",IFERROR(VLOOKUP($A13,'Lista de Precios'!$A:$H,6,0),"")) | G13: =IF($A13="","",IFERROR(VLOOKUP($A13,'Lista de Precios'!$A:$H,7,0),"")) | H13: =IF($A13="","",IFERROR(VLOOKUP($A13,'Lista de Precios'!$A:$H,8,0),""))
A14: =IFERROR(VLOOKUP($B$4,'Tabla Equiv'!$A:$I,8,0),"") | B14: =IF($A14="","",IFERROR(VLOOKUP($A14,'Lista de Precios'!$A:$H,2,0),"")) | C14: =IF($A14="","",IFERROR(VLOOKUP($A14,'Lista de Precios'!$A:$H,3,0),"")) | D14: =IF($A14="","",IFERROR(VLOOKUP($A14,'Lista de Precios'!$A:$H,4,0),"")) | E14: =IF($A14="","",IFERROR(VLOOKUP($A14,'Lista de Precios'!$A:$H,5,0),"")) | F14: =IF($A14="","",IFERROR(VLOOKUP($A14,'Lista de Precios'!$A:$H,6,0),"")) | G14: =IF($A14="","",IFERROR(VLOOKUP($A14,'Lista de Precios'!$A:$H,7,0),"")) | H14: =IF($A14="","",IFERROR(VLOOKUP($A14,'Lista de Precios'!$A:$H,8,0),""))
A15: =IFERROR(VLOOKUP($B$4,'Tabla Equiv'!$A:$I,9,0),"") | B15: =IF($A15="","",IFERROR(VLOOKUP($A15,'Lista de Precios'!$A:$H,2,0),"")) | C15: =IF($A15="","",IFERROR(VLOOKUP($A15,'Lista de Precios'!$A:$H,3,0),"")) | D15: =IF($A15="","",IFERROR(VLOOKUP($A15,'Lista de Precios'!$A:$H,4,0),"")) | E15: =IF($A15="","",IFERROR(VLOOKUP($A15,'Lista de Precios'!$A:$H,5,0),"")) | F15: =IF($A15="","",IFERROR(VLOOKUP($A15,'Lista de Precios'!$A:$H,6,0),"")) | G15: =IF($A15="","",IFERROR(VLOOKUP($A15,'Lista de Precios'!$A:$H,7,0),"")) | H15: =IF($A15="","",IFERROR(VLOOKUP($A15,'Lista de Precios'!$A:$H,8,0),""))

Sheet Tabla Equiv
A1: COD | B1: EQUIV_1 | C1: EQUIV_2 | D1: EQUIV_3 | E1: EQUIV_4 | F1: EQUIV_5 | G1: EQUIV_6 | H1: EQUIV_7 | I1: EQUIV_8
A2: CE 044 | B2: CE 301
A3: CE 046 | B3: CF 021
A4: CE 223 | B4: CF 033
A5: CE 225 | B5: CE 226
A6: CE 226 | B6: CE 225
A7: CE 301 | B7: CE 044
A8: CF 001 | B8: CF 589
A9: CF 002 | B9: CF 590 | C9: CF 591
A10: CF 003 | B10: CF 586
A11: CF 012 | B11: CF 671
A12: CF 013 | B12: CF 506
A13: CF 016 | B13: CF 604 | C13: CF 610
A14: CF 019 | B14: CF 656
A15: CF 020 | B15: CF 731 | C15: CF 887 | D15: CF 972
A16: CF 021 | B16: CE 046
A17: CF 033 | B17: CE 223
A18: CF 040 | B18: CF 763
A19: CF 042 | B19: CF 711
A20: CF 055 | B20: CF 241 | C20: CF 665 | D20: CF 674 | E20: CF 701 | F20: CF 759 | G20: CF 850 | H20: CF 889 | I20: CF 950 | J20: CF 990
A21: CF 057 | B21: CF 062
A22: CF 058 | B22: CF 620
A23: CF 062 | B23: CF 057
A24: CF 066 | B24: CF 605
A25: CF 098 | B25: CF 623
A26: CF 116 | B26: CF 705
A27: CF 181 | B27: CF 608
A28: CF 192 | B28: CF 606
A29: CF 241 | B29: CF 055 | C29: CF 665 | D29: CF 674 | E29: CF 701 | F29: CF 759 | G29: CF 850 | H29: CF 889 | I29: CF 950 | J29: CF 990
A30: CF 252 | B30: CF 654 | C30: CF 702 | D30: CF 851
A31: CF 402 | B31: CF 556
A32: CF 499 | B32: CF 703 | C32: CF 852
A33: CF 500 | B33: CF 502 | C33: CF 504 | D33: CF 853
A34: CF 502 | B34: CF 500 | C34: CF 504 | D34: CF 853
A35: CF 503 | B35: CF 588 | C35: CF 611
A36: CF 504 | B36: CF 500 | C36: CF 502 | D36: CF 853
A37: CF 505 | B37: CF 650 | C37: CF 753
A38: CF 506 | B38: CF 013
A39: CF 507 | B39: CF 635
A40: CF 508 | B40: CF 758
...

Sheet Lista de Precios
A1: COD | B1: TERMINAL | C1: ESP | D1: ANCH | E1: LARG | F1: MARCA | G1: MODELOS Y APLICACIONES | H1: PRECIO UNIT | I1: TIENE EQUIV.
A2: CC 101 | C2: 4.5 | D2: 8 | E2: 13 | F2: COBREADOS | G2: ATORNILLADOR BOSCH GSR 180 | H2: 12188
A3: CC 102 | C3: 3 | D3: 10 | E3: 13 | F3: COBREADOS | G3: ATORNILLADOR MAKITA CB 440 | H3: 9603
A4: CF 001 | B4: 1 | C4: 6 | D4: 9 | E4: 25 | F4: DOWEN PAGGIO | G4: LIJADORAS - PULIDORAS LIXA | H4: 3762 | I4: SI
A5: CF 002 | B5: 10 | C5: 6 | D5: 9 | E5: 20 | F5: DOWEN PAGGIO | G5: TALADROS MARK- NIG- NTX- LO- LV | H5: 3542 | I5: SI
A6: CF 003 | B6: 10 | C6: 5.6 | D6: 5.6 | E6: 16 | F6: DOWEN PAGGIO | G6: TALADROS MINI 8 Y 10- N 210/ 213/ 210 E/ 213 E/ 213 B | H6: 2783 | I6: SI
A7: CF 004 | B7: 10 | C7: 5 | D7: 7 | E7: 18 | F7: DOWEN PAGGIO | G7: RR | H7: 3762
A8: CF 005 | B8: 1 | C8: 6 | D8: 12 | E8: 20 | F8: DOWEN PAGGIO | G8: AMOL. 7"- MOD. AL 180 | H8: 5588
A9: CF 009 | B9: 5 | C9: 6.3 | D9: 6.3 | E9: 15 | F9: BLACK Y DECKER | G9: LINEA 700- TALADROS- CAL 2301/ 2303 LIJADORA/ TAL. VARIOS | H9: 2530
A10: CF 010 | B10: 5 | C10: DIAM | D10: 6 | E10: 15 | F10: BLACK Y DECKER | G10: TALADROS LINEA AR | H10: 3278
A11: CF 011 | B11: 7 | C11: 6.3 | D11: 6.3 | E11: 13 | F11: BLACK Y DECKER | G11: AMOL. 4 1/2 "- SAG 500- CALADORA M 531 | H11: 3278
A12: CF 012 | B12: 9 | C12: 6.3 | D12: 8 | E12: 15 | F12: BLACK Y DECKER | G12: AMOLADORA DE 4 1/2 " P5432- P 5411 C / GUIA | H12: 3377 | I12: SI
A13: CF 012 | B13: 9 | C13: 6.3 | D13: 8 | E13: 15 | F13: BLACK Y DECKER | G13: KG 11/ KG75 (CON AVISO DE DESGASTE) | H13: 3377 | I13: SI
A14: CF 013 | B14: 7 | C14: 6.3 | D14: 9.3 | E14: 14 | F14: BLACK Y DECKER | G14: SIERRA CIRCULAR DE 7 1/4 " Y 9" | H14: 2200 | I14: SI
A15: CF 014 | B15: 1 | C15: 7 | D15: 12 | E15: 26 | F15: BLACK Y DECKER | G15: AMOLADORAS SMEA DE 7 " Y 9" | H15: 5500
A16: CF 015 | B16: 1 | C16: 6 | D16: 12 | E16: 21 | F16: BLACK Y DECKER | G16: AMOLADORA AG/C- AMOL. 7" HD 2180- AMOL. 9" HD 2230 | H16: 5588
A17: CF 016 | B17: 15 | C17: 6.3 | D17: 16 | E17: 22 | F17: BOSCH | G17: AMOLADORAS 7" Y 9" - MOD. 1321/ 2 - 1331/ 2 CON AVISO DE DESGASTE | H17: 5643 | I17: SI
A18: CF 017 | B18: 2 | C18: 5 | D18: 8 | E18: 17 | F18: BOSCH | G18: AMOL 41/2¨ GWS 6-115/GWS 7-115/GWS 7-115ET/GWS 8-115 (CON AVISO DE DESGASTE) | H18: 3762
A19: CF 018 | B19: 11 | C19: 6 | D19: 14 | E19: 20 | F19: BOSCH | G19: AMOL. DE 7" Y 9"- MOD. ALEMAN 1307/ 1309 | H19: 4796
A20: CF 019 | B20: 10 | C20: 5 | D20: 8 | E20: 17 | F20: BOSCH | G20: TALADROS MOD. 1106/ 350/ GBM 10/ 13 RB/ 1163/ 1171/ 1184/ 11226 | H20: 3542 | I20: SI
A21: CF 020 | B21: 2 | C21: 6.3 | D21: 16 | E21: 22 | F21: BOSCH | G21: AMOL. 7 y 9" GWS 22-10/22-230/GWS 24-180/24-230/GWS 26-180(CON AVISO) | H21: 5643 | I21: SI
A22: CF 021 | B22: 10 | C22: 6.3 | D22: 6.3 | E22: 16 | F22: BOSCH | G22: TAL. PER. 13- MOD. 3161/ 3238/ 1169 CAL. PST 54 PE | H22: 3278 | I22: SI
A23: CF 022 | B23: 15 | C23: 6.3 | D23: 10 | E23: 17 | F23: BOSCH | G23: MARTILLO MODELO 11205 CON AVISO | H23: 3542
A24: CF 023 | B24: 14 | C24: 6.3 | D24: 12.3 | E24: 19 | F24: BOSCH | G24: LIJADORA MOD. 1317 | H24: 4554
A25: CF 023 | B25: 14 | C25: 6.3 | D25: 12.3 | E25: 19 | F25: BOSCH | G25: CON AVISO DE DESGASTE | H25: 4554
A26: CF 024 | B26: 18 | C26: 6 | D26: 6 | E26: 16 | F26: BOSCH | G26: AMOL. DE 4 1/2" - MOD. 1327 | H26: 3278
A27: CF 025 | B27: 16 | C27: 6.5 | D27: 8 | E27: 17 | F27: BOSCH | G27: TALADRO ROTOPERCUTOR MOD. 0173/ 1111 | H27: 3278
A28: CF 027 | B28: 10 | C28: 6 | D28: 9 | E28: 27 | F28: DOVER | G28: LIJADORA- PULIDORA | H28: 5005
A29: CF 028 | B29: 1 | C29: 6 | D29: 12 | E29: 27 | F29: DOVER | G29: AMOLADORA DE 7 Y 9- LINEA 80 | H29: 5588
A30: CF 029 | B30: 1 | C30: 6.4 | D30: 16 | E30: 20 | F30: DOVER | G30: AMOLADORA DE 7 Y 9- LINEA 90 | H30: 5181
A31: CF 030 | B31: 5 | C31: 6 | D31: 6 | E31: 12 | F31: DOVER | G31: AMOLADORA DE 4 (MODELO VIEJO) | H31: 2530
A32: CF 031 | B32: 10 | C32: 6 | D32: 6 | E32: 18 | F32: DOVER | G32: AMOLADORA DE 4 (MODELO NUEVO) | H32: 3278
A33: CF 033 | B33: 5 | C33: 4 | D33: 5 | E33: 15 | F33: DREMEL | G33: MINITORNO | H33: 4235 | I33: SI
A34: CF 034 | B34: 5 | C34: 4 | D34: 4 | E34: 12 | F34: DRILL - MET | G34: MINI DRIL | H34: 4235
A35: CF 035 | B35: 7 | C35: 5 | D35: 7 | E35: 19 | F35: DRILL - MET | G35: TORNO 1/4" | H35: 4235
A36: CF 036 | B36: 7 | C36: 5 | D36: 7 | E36: 13 | F36: DRILL - MET | G36: TORNO 1/8" | H36: 4235
A37: CF 040 | B37: 1 | C37: 7 | D37: 17 | E37: 17 | F37: HITACHI | G37: PDM 180/230- PDU 180/230- DPU 180/230-PDH 180- PSU 7/8/9- PSP 9- CC 16 | H37: 5423 | I37: SI
A38: CF 041 | B38: 10 | C38: 6.5 | D38: 7.5 | E38: 13 | F38: HITACHI | G38: PDM 115.PDP 115-PDS 115- F 20- F 20 A- JH 60- JHV 60. JH 560 | H38: 2783
A39: CF 042 | B39: 1 | C39: 7 | D39: 11 | E39: 17 | F39: HITACHI | G39: SAT 180- F 30 A-SB 75- PSU 6- PS 7 B-TR 8- PR 25 B- PR 38 B | H39: 5533 | I39: SI
A40: CF 043 | B40: 10 | C40: 6 | D40: 6 | E40: 13 | F40: HITACHI | G40: FFE 20- FH 35- FSO 93 | H40: 3278
...
